Workbook
Name Argonian_Female: #REF!
Name Human_Male: #REF!

Sheet NPC List
A1: FormID | B1: NPC EditorID | C1: NPC Name | D1: NPC Race | E1: NPC Gender | F1: Vanilla Hair ID | G1: Vanilla Hair SPID Form
A2: 0008774F | B2: Abelone | C2: Abelone | D2: Nord | E2: Female | F2: HairFemaleNord07 | G2: {=IF(B2="", "", LET(_xlpm.spell, IFERROR(IF(F2="", "", INDEX(_xlws.FILTER(Hairstyles!$F:$F, ISNUMBER(SEARCH(F2, Hairstyles!$B:$B))), 1)), "No Spell for Hairstyle"), _xlpm.vanillaPrefix, IF(LEFT(_xlpm.spell, 7)="Uvi_Wig", "", ";"), ";" & IF(C2="", B2, C2) & IF(M2="", "", " ("&M2&")") & CHAR(10) & _xlpm.vanillaPrefix & "Keyword = Uvi_Wig_Distr_KYWD|" & B2 & CHAR(10) & _xlpm.vanillaPrefix & "Spell = " & _xlpm.spell & "|" & B2 ) )} -> ;Abelone ;Keyword = Uvi_Wig_Distr_KYWD|Abelone ;Spell = No Spell for Hairstyle|Abelone
A3: 000D3E79 | B3: AcolyteJenssen | C3: Acolyte Jenssen | D3: Nord | E3: Male | F3: HairMaleNord05 | G3: {=IF(B3="", "", LET(_xlpm.spell, IFERROR(IF(F3="", "", INDEX(_xlws.FILTER(Hairstyles!$F:$F, ISNUMBER(SEARCH(F3, Hairstyles!$B:$B))), 1)), "No Spell for Hairstyle"), _xlpm.vanillaPrefix, IF(LEFT(_xlpm.spell, 7)="Uvi_Wig", "", ";"), ";" & IF(C3="", B3, C3) & IF(M3="", "", " ("&M3&")") & CHAR(10) & _xlpm.vanillaPrefix & "Keyword = Uvi_Wig_Distr_KYWD|" & B3 & CHAR(10) & _xlpm.vanillaPrefix & "Spell = " & _xlpm.spell & "|" & B3 ) )} -> ;Acolyte Jenssen ;Keyword = Uvi_Wig_Distr_KYWD|AcolyteJenssen ;Spell = No Spell for Hairstyle|AcolyteJenssen
A4: 00013385 | B4: Adara | C4: Adara | D4: RedguardChild | E4: Female | F4: HairFemaleRedguardChild01 | G4: {=IF(B4="", "", LET(_xlpm.spell, IFERROR(IF(F4="", "", INDEX(_xlws.FILTER(Hairstyles!$F:$F, ISNUMBER(SEARCH(F4, Hairstyles!$B:$B))), 1)), "No Spell for Hairstyle"), _xlpm.vanillaPrefix, IF(LEFT(_xlpm.spell, 7)="Uvi_Wig", "", ";"), ";" & IF(C4="", B4, C4) & IF(M4="", "", " ("&M4&")") & CHAR(10) & _xlpm.vanillaPrefix & "Keyword = Uvi_Wig_Distr_KYWD|" & B4 & CHAR(10) & _xlpm.vanillaPrefix & "Spell = " & _xlpm.spell & "|" & B4 ) )} -> ;Adara ;Keyword = Uvi_Wig_Distr_KYWD|Adara ;Spell = No Spell for Hairstyle|Adara
A5: 02008D7A | B5: DLC1dunRedwaterDenAddict4 | C5: Addict | D5: Elder | E5: Female | F5: HairFemaleNord12 | G5: {=IF(B5="", "", LET(_xlpm.spell, IFERROR(IF(F5="", "", INDEX(_xlws.FILTER(Hairstyles!$F:$F, ISNUMBER(SEARCH(F5, Hairstyles!$B:$B))), 1)), "No Spell for Hairstyle"), _xlpm.vanillaPrefix, IF(LEFT(_xlpm.spell, 7)="Uvi_Wig", "", ";"), ";" & IF(C5="", B5, C5) & IF(M5="", "", " ("&M5&")") & CHAR(10) & _xlpm.vanillaPrefix & "Keyword = Uvi_Wig_Distr_KYWD|" & B5 & CHAR(10) & _xlpm.vanillaPrefix & "Spell = " & _xlpm.spell & "|" & B5 ) )} -> ;Addict ;Keyword = Uvi_Wig_Distr_KYWD|DLC1dunRedwaterDenAddict4 ;Spell = No Spell for Hairstyle|DLC1dunRedwaterDenAddict4
A6: 00013255 | B6: Addvar | C6: Addvar | D6: Nord | E6: Male | F6: HairMaleNord09 | G6: {=IF(B6="", "", LET(_xlpm.spell, IFERROR(IF(F6="", "", INDEX(_xlws.FILTER(Hairstyles!$F:$F, ISNUMBER(SEARCH(F6, Hairstyles!$B:$B))), 1)), "No Spell for Hairstyle"), _xlpm.vanillaPrefix, IF(LEFT(_xlpm.spell, 7)="Uvi_Wig", "", ";"), ";" & IF(C6="", B6, C6) & IF(M6="", "", " ("&M6&")") & CHAR(10) & _xlpm.vanillaPrefix & "Keyword = Uvi_Wig_Distr_KYWD|" & B6 & CHAR(10) & _xlpm.vanillaPrefix & "Spell = " & _xlpm.spell & "|" & B6 ) )} -> ;Addvar ;Keyword = Uvi_Wig_Distr_KYWD|Addvar ;Spell = No Spell for Hairstyle|Addvar
A7: 00019DC7 | B7: Addvild | C7: Addvild | D7: Nord | E7: Male | F7: HairMaleNord09 | G7: {=IF(B7="", "", LET(_xlpm.spell, IFERROR(IF(F7="", "", INDEX(_xlws.FILTER(Hairstyles!$F:$F, ISNUMBER(SEARCH(F7, Hairstyles!$B:$B))), 1)), "No Spell for Hairstyle"), _xlpm.vanillaPrefix, IF(LEFT(_xlpm.spell, 7)="Uvi_Wig", "", ";"), ";" & IF(C7="", B7, C7) & IF(M7="", "", " ("&M7&")") & CHAR(10) & _xlpm.vanillaPrefix & "Keyword = Uvi_Wig_Distr_KYWD|" & B7 & CHAR(10) & _xlpm.vanillaPrefix & "Spell = " & _xlpm.spell & "|" & B7 ) )} -> ;Addvild ;Keyword = Uvi_Wig_Distr_KYWD|Addvild ;Spell = No Spell for Hairstyle|Addvild
A8: 000661AD | B8: Adeber | C8: Adeber | D8: Breton | E8: Male | F8: HairMaleNord07 | G8: {=IF(B8="", "", LET(_xlpm.spell, IFERROR(IF(F8="", "", INDEX(_xlws.FILTER(Hairstyles!$F:$F, ISNUMBER(SEARCH(F8, Hairstyles!$B:$B))), 1)), "No Spell for Hairstyle"), _xlpm.vanillaPrefix, IF(LEFT(_xlpm.spell, 7)="Uvi_Wig", "", ";"), ";" & IF(C8="", B8, C8) & IF(M8="", "", " ("&M8&")") & CHAR(10) & _xlpm.vanillaPrefix & "Keyword = Uvi_Wig_Distr_KYWD|" & B8 & CHAR(10) & _xlpm.vanillaPrefix & "Spell = " & _xlpm.spell & "|" & B8 ) )} -> ;Adeber ;Keyword = Uvi_Wig_Distr_KYWD|Adeber ;Spell = No Spell for Hairstyle|Adeber
A9: 0001411D | B9: Adelaisa | C9: Adelaisa Vendicci | D9: Imperial | E9: Female | F9: HairFemaleNord11 | G9: {=IF(B9="", "", LET(_xlpm.spell, IFERROR(IF(F9="", "", INDEX(_xlws.FILTER(Hairstyles!$F:$F, ISNUMBER(SEARCH(F9, Hairstyles!$B:$B))), 1)), "No Spell for Hairstyle"), _xlpm.vanillaPrefix, IF(LEFT(_xlpm.spell, 7)="Uvi_Wig", "", ";"), ";" & IF(C9="", B9, C9) & IF(M9="", "", " ("&M9&")") & CHAR(10) & _xlpm.vanillaPrefix & "Keyword = Uvi_Wig_Distr_KYWD|" & B9 & CHAR(10) & _xlpm.vanillaPrefix & "Spell = " & _xlpm.spell & "|" & B9 ) )} -> ;Adelaisa Vendicci ;Keyword = Uvi_Wig_Distr_KYWD|Adelaisa ;Spell = No Spell for Hairstyle|Adelaisa
A10: 0001411E | B10: Adisla | C10: Adisla | D10: Nord | E10: Female | F10: HairFemaleNord05 | G10: {=IF(B10="", "", LET(_xlpm.spell, IFERROR(IF(F10="", "", INDEX(_xlws.FILTER(Hairstyles!$F:$F, ISNUMBER(SEARCH(F10, Hairstyles!$B:$B))), 1)), "No Spell for Hairstyle"), _xlpm.vanillaPrefix, IF(LEFT(_xlpm.spell, 7)="Uvi_Wig", "", ";"), ";" & IF(C10="", B10, C10) & IF(M10="", "", " ("&M10&")") & CHAR(10) & _xlpm.vanillaPrefix & "Keyword = Uvi_Wig_Distr_KYWD|" & B10 & CHAR(10) & _xlpm.vanillaPrefix & "Spell = " & _xlpm.spell & "|" & B10 ) )} -> ;Adisla ;Keyword = Uvi_Wig_Distr_KYWD|Adisla ;Spell = No Spell for Hairstyle|Adisla
A11: 0001413C | B11: AdonatoLeotelli | C11: Adonato Leotelli | D11: Imperial | E11: Male | F11: HairMaleElder4 | G11: {=IF(B11="", "", LET(_xlpm.spell, IFERROR(IF(F11="", "", INDEX(_xlws.FILTER(Hairstyles!$F:$F, ISNUMBER(SEARCH(F11, Hairstyles!$B:$B))), 1)), "No Spell for Hairstyle"), _xlpm.vanillaPrefix, IF(LEFT(_xlpm.spell, 7)="Uvi_Wig", "", ";"), ";" & IF(C11="", B11, C11) & IF(M11="", "", " ("&M11&")") & CHAR(10) & _xlpm.vanillaPrefix & "Keyword = Uvi_Wig_Distr_KYWD|" & B11 & CHAR(10) & _xlpm.vanillaPrefix & "Spell = " & _xlpm.spell & "|" & B11 ) )} -> ;Adonato Leotelli ;Keyword = Uvi_Wig_Distr_KYWD|AdonatoLeotelli ;Spell = No Spell for Hairstyle|AdonatoLeotelli
A12: 00013BB9 | B12: AdrianneAvenicci | C12: Adrianne Avenicci | D12: Imperial | E12: Female | F12: HairFemaleNord14 | G12: {=IF(B12="", "", LET(_xlpm.spell, IFERROR(IF(F12="", "", INDEX(_xlws.FILTER(Hairstyles!$F:$F, ISNUMBER(SEARCH(F12, Hairstyles!$B:$B))), 1)), "No Spell for Hairstyle"), _xlpm.vanillaPrefix, IF(LEFT(_xlpm.spell, 7)="Uvi_Wig", "", ";"), ";" & IF(C12="", B12, C12) & IF(M12="", "", " ("&M12&")") & CHAR(10) & _xlpm.vanillaPrefix & "Keyword = Uvi_Wig_Distr_KYWD|" & B12 & CHAR(10) & _xlpm.vanillaPrefix & "Spell = " & _xlpm.spell & "|" & B12 ) )} -> ;Adrianne Avenicci ;Keyword = Uvi_Wig_Distr_KYWD|AdrianneAvenicci ;Spell = No Spell for Hairstyle|AdrianneAvenicci
A13: 02018280 | B13: DLC2RRAdrilArano | C13: Adril Arano | D13: DarkElf | E13: Male | F13: HairMaleDarkElf01 | G13: {=IF(B13="", "", LET(_xlpm.spell, IFERROR(IF(F13="", "", INDEX(_xlws.FILTER(Hairstyles!$F:$F, ISNUMBER(SEARCH(F13, Hairstyles!$B:$B))), 1)), "No Spell for Hairstyle"), _xlpm.vanillaPrefix, IF(LEFT(_xlpm.spell, 7)="Uvi_Wig", "", ";"), ";" & IF(C13="", B13, C13) & IF(M13="", "", " ("&M13&")") & CHAR(10) & _xlpm.vanillaPrefix & "Keyword = Uvi_Wig_Distr_KYWD|" & B13 & CHAR(10) & _xlpm.vanillaPrefix & "Spell = " & _xlpm.spell & "|" & B13 ) )} -> ;Adril Arano ;Keyword = Uvi_Wig_Distr_KYWD|DLC2RRAdrilArano ;Spell = No Spell for Hairstyle|DLC2RRAdrilArano
... A1757: 0001B1D0 | B1757: Zaynabi | C1757: Zaynabi | D1757: Khajiit | E1757: Female | F1757: HairKhajiitFemale06 | G1757: {=IF(B1757="", "", LET(_xlpm.spell, IFERROR(IF(F1757="", "", INDEX(_xlws.FILTER(Hairstyles!$F:$F, ISNUMBER(SEARCH(F1757, Hairstyles!$B:$B))), 1)), "No Spell for Hairstyle"), _xlpm.vanillaPrefix, IF(LEFT(_xlpm.spell, 7)="Uvi_Wig", "", ";"), ";" & IF(C1757="", B1757, C1757) & IF(M1757="", "", " ("&M1757&")") & CHAR(10) & _xlpm.vanillaPrefix & "Keyword = Uvi_Wig_Distr_KYWD|" & B1757 & CHAR(10) & _xlpm.vanillaPrefix & "Spell = " & _xlpm.spell & "|" & B1757 ) )} -> ;Zaynabi ;Keyword = Uvi_Wig_Distr_KYWD|Zaynabi ;Spell = No Spell for Hairstyle|Zaynabi
A1758: 000AD3A5 | B1758: C04DeadKodlak | D1758: Nord | E1758: Male | F1758: HairMaleNord06 | G1758: {=IF(B1758="", "", LET(_xlpm.spell, IFERROR(IF(F1758="", "", INDEX(_xlws.FILTER(Hairstyles!$F:$F, ISNUMBER(SEARCH(F1758, Hairstyles!$B:$B))), 1)), "No Spell for Hairstyle"), _xlpm.vanillaPrefix, IF(LEFT(_xlpm.spell, 7)="Uvi_Wig", "", ";"), ";" & IF(C1758="", B1758, C1758) & IF(M1758="", "", " ("&M1758&")") & CHAR(10) & _xlpm.vanillaPrefix & "Keyword = Uvi_Wig_Distr_KYWD|" & B1758 & CHAR(10) & _xlpm.vanillaPrefix & "Spell = " & _xlpm.spell & "|" & B1758 ) )} -> ;C04DeadKodlak ;Keyword = Uvi_Wig_Distr_KYWD|C04DeadKodlak ;Spell = No Spell for Hairstyle|C04DeadKodlak
A1759: 000DCCC0 | B1759: C06DeadKodlak | D1759: Nord | E1759: Male | F1759: HairMaleNord06 | G1759: {=IF(B1759="", "", LET(_xlpm.spell, IFERROR(IF(F1759="", "", INDEX(_xlws.FILTER(Hairstyles!$F:$F, ISNUMBER(SEARCH(F1759, Hairstyles!$B:$B))), 1)), "No Spell for Hairstyle"), _xlpm.vanillaPrefix, IF(LEFT(_xlpm.spell, 7)="Uvi_Wig", "", ";"), ";" & IF(C1759="", B1759, C1759) & IF(M1759="", "", " ("&M1759&")") & CHAR(10) & _xlpm.vanillaPrefix & "Keyword = Uvi_Wig_Distr_KYWD|" & B1759 & CHAR(10) & _xlpm.vanillaPrefix & "Spell = " & _xlpm.spell & "|" & B1759 ) )} -> ;C06DeadKodlak ;Keyword = Uvi_Wig_Distr_KYWD|C06DeadKodlak ;Spell = No Spell for Hairstyle|C06DeadKodlak
A1760: 0001720B | B1760: C06KodlaksGhost | D1760: Nord | E1760: Male | F1760: HairMaleNord06 | G1760: {=IF(B1760="", "", LET(_xlpm.spell, IFERROR(IF(F1760="", "", INDEX(_xlws.FILTER(Hairstyles!$F:$F, ISNUMBER(SEARCH(F1760, Hairstyles!$B:$B))), 1)), "No Spell for Hairstyle"), _xlpm.vanillaPrefix, IF(LEFT(_xlpm.spell, 7)="Uvi_Wig", "", ";"), ";" & IF(C1760="", B1760, C1760) & IF(M1760="", "", " ("&M1760&")") & CHAR(10) & _xlpm.vanillaPrefix & "Keyword = Uvi_Wig_Distr_KYWD|" & B1760 & CHAR(10) & _xlpm.vanillaPrefix & "Spell = " & _xlpm.spell & "|" & B1760 ) )} -> ;C06KodlaksGhost ;Keyword = Uvi_Wig_Distr_KYWD|C06KodlaksGhost ;Spell = No Spell for Hairstyle|C06KodlaksGhost
A1761: 000A5794 | B1761: CorpsePrisonerNordMale | D1761: Nord | E1761: Male | F1761: HairMaleNord04 | G1761: {=IF(B1761="", "", LET(_xlpm.spell, IFERROR(IF(F1761="", "", INDEX(_xlws.FILTER(Hairstyles!$F:$F, ISNUMBER(SEARCH(F1761, Hairstyles!$B:$B))), 1)), "No Spell for Hairstyle"), _xlpm.vanillaPrefix, IF(LEFT(_xlpm.spell, 7)="Uvi_Wig", "", ";"), ";" & IF(C1761="", B1761, C1761) & IF(M1761="", "", " ("&M1761&")") & CHAR(10) & _xlpm.vanillaPrefix & "Keyword = Uvi_Wig_Distr_KYWD|" & B1761 & CHAR(10) & _xlpm.vanillaPrefix & "Spell = " & _xlpm.spell & "|" & B1761 ) )} -> ;CorpsePrisonerNordMale ;Keyword = Uvi_Wig_Distr_KYWD|CorpsePrisonerNordMale ;Spell = No Spell for Hairstyle|CorpsePrisonerNordMale
A1762: 000DC25D | B1762: CW03ImperialScout | D1762: Imperial | E1762: Male | F1762: HairMaleNord09 | G1762: {=IF(B1762="", "", LET(_xlpm.spell, IFERROR(IF(F1762="", "", INDEX(_xlws.FILTER(Hairstyles!$F:$F, ISNUMBER(SEARCH(F1762, Hairstyles!$B:$B))), 1)), "No Spell for Hairstyle"), _xlpm.vanillaPrefix, IF(LEFT(_xlpm.spell, 7)="Uvi_Wig", "", ";"), ";" & IF(C1762="", B1762, C1762) & IF(M1762="", "", " ("&M1762&")") & CHAR(10) & _xlpm.vanillaPrefix & "Keyword = Uvi_Wig_Distr_KYWD|" & B1762 & CHAR(10) & _xlpm.vanillaPrefix & "Spell = " & _xlpm.spell & "|" & B1762 ) )} -> ;CW03ImperialScout ;Keyword = Uvi_Wig_Distr_KYWD|CW03ImperialScout ;Spell = No Spell for Hairstyle|CW03ImperialScout
A1763: 000770B2 | B1763: CWMission06DissaffectSoldierImperial1 | D1763: Imperial | E1763: Male | F1763: HairMaleNord11 | G1763: {=IF(B1763="", "", LET(_xlpm.spell, IFERROR(IF(F1763="", "", INDEX(_xlws.FILTER(Hairstyles!$F:$F, ISNUMBER(SEARCH(F1763, Hairstyles!$B:$B))), 1)), "No Spell for Hairstyle"), _xlpm.vanillaPrefix, IF(LEFT(_xlpm.spell, 7)="Uvi_Wig", "", ";"), ";" & IF(C1763="", B1763, C1763) & IF(M1763="", "", " ("&M1763&")") & CHAR(10) & _xlpm.vanillaPrefix & "Keyword = Uvi_Wig_Distr_KYWD|" & B1763 & CHAR(10) & _xlpm.vanillaPrefix & "Spell = " & _xlpm.spell & "|" & B1763 ) )} -> ;CWMission06DissaffectSoldierImperial1 ;Keyword = Uvi_Wig_Distr_KYWD|CWMission06DissaffectSoldierImperial1 ;Spell = No Spell for Hairstyle|CWMission06DissaffectSoldierImperial1
A1764: 000770B6 | B1764: CWMission06DissaffectSoldierSons1 | D1764: Nord | E1764: Male | F1764: HairMaleNord15 | G1764: {=IF(B1764="", "", LET(_xlpm.spell, IFERROR(IF(F1764="", "", INDEX(_xlws.FILTER(Hairstyles!$F:$F, ISNUMBER(SEARCH(F1764, Hairstyles!$B:$B))), 1)), "No Spell for Hairstyle"), _xlpm.vanillaPrefix, IF(LEFT(_xlpm.spell, 7)="Uvi_Wig", "", ";"), ";" & IF(C1764="", B1764, C1764) & IF(M1764="", "", " ("&M1764&")") & CHAR(10) & _xlpm.vanillaPrefix & "Keyword = Uvi_Wig_Distr_KYWD|" & B1764 & CHAR(10) & _xlpm.vanillaPrefix & "Spell = " & _xlpm.spell & "|" & B1764 ) )} -> ;CWMission06DissaffectSoldierSons1 ;Keyword = Uvi_Wig_Distr_KYWD|CWMission06DissaffectSoldierSons1 ;Spell = No Spell for Hairstyle|CWMission06DissaffectSoldierSons1
A1765: 000770BA | B1765: CWMission06LoyalistLeaderImperial | D1765: Imperial | E1765: Male | F1765: HairMaleElder6 | G1765: {=IF(B1765="", "", LET(_xlpm.spell, IFERROR(IF(F1765="", "", INDEX(_xlws.FILTER(Hairstyles!$F:$F, ISNUMBER(SEARCH(F1765, Hairstyles!$B:$B))), 1)), "No Spell for Hairstyle"), _xlpm.vanillaPrefix, IF(LEFT(_xlpm.spell, 7)="Uvi_Wig", "", ";"), ";" & IF(C1765="", B1765, C1765) & IF(M1765="", "", " ("&M1765&")") & CHAR(10) & _xlpm.vanillaPrefix & "Keyword = Uvi_Wig_Distr_KYWD|" & B1765 & CHAR(10) & _xlpm.vanillaPrefix & "Spell = " & _xlpm.spell & "|" & B1765 ) )} -> ;CWMission06LoyalistLeaderImperial ;Keyword = Uvi_Wig_Distr_KYWD|CWMission06LoyalistLeaderImperial ;Spell = No Spell for Hairstyle|CWMission06LoyalistLeaderImperial
A1766: 000770BB | B1766: CWMission06LoyalistLeaderSons | D1766: Nord | E1766: Male | F1766: HairMaleElder3 | G1766: {=IF(B1766="", "", LET(_xlpm.spell, IFERROR(IF(F1766="", "", INDEX(_xlws.FILTER(Hairstyles!$F:$F, ISNUMBER(SEARCH(F1766, Hairstyles!$B:$B))), 1)), "No Spell for Hairstyle"), _xlpm.vanillaPrefix, IF(LEFT(_xlpm.spell, 7)="Uvi_Wig", "", ";"), ";" & IF(C1766="", B1766, C1766) & IF(M1766="", "", " ("&M1766&")") & CHAR(10) & _xlpm.vanillaPrefix & "Keyword = Uvi_Wig_Distr_KYWD|" & B1766 & CHAR(10) & _xlpm.vanillaPrefix & "Spell = " & _xlpm.spell & "|" & B1766 ) )} -> ;CWMission06LoyalistLeaderSons ;Keyword = Uvi_Wig_Distr_KYWD|CWMission06LoyalistLeaderSons ;Spell = No Spell for Hairstyle|CWMission06LoyalistLeaderSons
A1767: 0001675D | B1767: CWPrisonerImperial | D1767: Imperial | E1767: Male | F1767: HairMaleNord01 | G1767: {=IF(B1767="", "", LET(_xlpm.spell, IFERROR(IF(F1767="", "", INDEX(_xlws.FILTER(Hairstyles!$F:$F, ISNUMBER(SEARCH(F1767, Hairstyles!$B:$B))), 1)), "No Spell for Hairstyle"), _xlpm.vanillaPrefix, IF(LEFT(_xlpm.spell, 7)="Uvi_Wig", "", ";"), ";" & IF(C1767="", B1767, C1767) & IF(M1767="", "", " ("&M1767&")") & CHAR(10) & _xlpm.vanillaPrefix & "Keyword = Uvi_Wig_Distr_KYWD|" & B1767 & CHAR(10) & _xlpm.vanillaPrefix & "Spell = " & _xlpm.spell & "|" & B1767 ) )} -> ;CWPrisonerImperial ;Keyword = Uvi_Wig_Distr_KYWD|CWPrisonerImperial ;Spell = No Spell for Hairstyle|CWPrisonerImperial
A1768: 0010D4B2 | B1768: CWPrisonerImperialA | D1768: Imperial | E1768: Male | F1768: HairMaleNord07 | G1768: {=IF(B1768="", "", LET(_xlpm.spell, IFERROR(IF(F1768="", "", INDEX(_xlws.FILTER(Hairstyles!$F:$F, ISNUMBER(SEARCH(F1768, Hairstyles!$B:$B))), 1)), "No Spell for Hairstyle"), _xlpm.vanillaPrefix, IF(LEFT(_xlpm.spell, 7)="Uvi_Wig", "", ";"), ";" & IF(C1768="", B1768, C1768) & IF(M1768="", "", " ("&M1768&")") & CHAR(10) & _xlpm.vanillaPrefix & "Keyword = Uvi_Wig_Distr_KYWD|" & B1768 & CHAR(10) & _xlpm.vanillaPrefix & "Spell = " & _xlpm.spell & "|" & B1768 ) )} -> ;CWPrisonerImperialA ;Keyword = Uvi_Wig_Distr_KYWD|CWPrisonerImperialA ;Spell = No Spell for Hairstyle|CWPrisonerImperialA
A1769: 0010D4B3 | B1769: CWPrisonerImperialB | D1769: Imperial | E1769: Male | F1769: HairMaleNord12 | G1769: {=IF(B1769="", "", LET(_xlpm.spell, IFERROR(IF(F1769="", "", INDEX(_xlws.FILTER(Hairstyles!$F:$F, ISNUMBER(SEARCH(F1769, Hairstyles!$B:$B))), 1)), "No Spell for Hairstyle"), _xlpm.vanillaPrefix, IF(LEFT(_xlpm.spell, 7)="Uvi_Wig", "", ";"), ";" & IF(C1769="", B1769, C1769) & IF(M1769="", "", " ("&M1769&")") & CHAR(10) & _xlpm.vanillaPrefix & "Keyword = Uvi_Wig_Distr_KYWD|" & B1769 & CHAR(10) & _xlpm.vanillaPrefix & "Spell = " & _xlpm.spell & "|" & B1769 ) )} -> ;CWPrisonerImperialB ;Keyword = Uvi_Wig_Distr_KYWD|CWPrisonerImperialB ;Spell = No Spell for Hairstyle|CWPrisonerImperialB
... A3514: 000590EF | B3514: WhiterunJailPrisoner | D3514: Nord | E3514: Male | F3514: HairMaleNord10 | G3514: {=IF(B3514="", "", LET(_xlpm.spell, IFERROR(IF(F3514="", "", INDEX(_xlws.FILTER(Hairstyles!$F:$F, ISNUMBER(SEARCH(F3514, Hairstyles!$B:$B))), 1)), "No Spell for Hairstyle"), _xlpm.vanillaPrefix, IF(LEFT(_xlpm.spell, 7)="Uvi_Wig", "", ";"), ";" & IF(C3514="", B3514, C3514) & IF(M3514="", "", " ("&M3514&")") & CHAR(10) & _xlpm.vanillaPrefix & "Keyword = Uvi_Wig_Distr_KYWD|" & B3514 & CHAR(10) & _xlpm.vanillaPrefix & "Spell = " & _xlpm.spell & "|" & B3514 ) )} -> ;WhiterunJailPrisoner ;Keyword = Uvi_Wig_Distr_KYWD|WhiterunJailPrisoner ;Spell = No Spell for Hairstyle|WhiterunJailPrisoner

Sheet Hairstyles
A1: Mod | B1: Hairstyle EditorIDs | C1: Hairstyle Name | D1: Zoom F | E1: Zoom S | F1: Wig Spell EditorID | G1: Valid Race Types | H1: Valid Genders | I1: Race_Gender Categories | J1: Requirements | K1: Race/Gender Specific Requirements | L1: Process_Screenshots CSV
A2: Vanilla | B2: HairArgonianFemale00,HairArgonianMale00,HairKhajiit00,HairKhajiitMale10,KhajiitFemaleEarTufts,KhajiitMaleEarTufts,NoHair | C2: Vanilla - Bald | D2: 1 | E2: 1 | F2: Uvi_Wig_Spell_VHRU_BaldCap | I2: Argonian_Male, Argonian_Female, Elf_Male, Elf_Female, Human_Male, Human_Female, HumanChild_Male, HumanChild_Female, Khajiit_Male, Khajiit_Female, Orc_Male, Orc_Female | J2: VHR,VHRWU | L2: =SUBSTITUTE(SUBSTITUTE(SUBSTITUTE(SUBSTITUTE(SUBSTITUTE(C2," ",""),"'",""),"(",""),")",""),"-","_")&","&D2&","&E2 -> Vanilla_Bald,1,1
A3: Vanilla | B3: HairArgonianFemale01,HairArgonianMale01 | C3: Vanilla - Argonian 01 | D3: 1 | E3: 1 | F3: Uvi_Wig_Spell_VHRU_Argonian01 | I3: Argonian_Female, Argonian_Male | J3: VHR,VHRWU | L3: =SUBSTITUTE(SUBSTITUTE(SUBSTITUTE(SUBSTITUTE(SUBSTITUTE(C3," ",""),"'",""),"(",""),")",""),"-","_")&","&D3&","&E3 -> Vanilla_Argonian01,1,1
A4: Vanilla | B4: HairArgonianFemale02,HairArgonianMale02 | C4: Vanilla - Argonian 02 | D4: 1 | E4: 1 | F4: Uvi_Wig_Spell_VHRU_Argonian02 | I4: Argonian_Female, Argonian_Male | J4: VHR,VHRWU | L4: =SUBSTITUTE(SUBSTITUTE(SUBSTITUTE(SUBSTITUTE(SUBSTITUTE(C4," ",""),"'",""),"(",""),")",""),"-","_")&","&D4&","&E4 -> Vanilla_Argonian02,1,1
A5: Vanilla | B5: HairArgonianFemale03,HairArgonianMale03 | C5: Vanilla - Argonian 03 | D5: 1 | E5: 1 | F5: Uvi_Wig_Spell_VHRU_Argonian03 | I5: Argonian_Female, Argonian_Male | J5: VHR,VHRWU | L5: =SUBSTITUTE(SUBSTITUTE(SUBSTITUTE(SUBSTITUTE(SUBSTITUTE(C5," ",""),"'",""),"(",""),")",""),"-","_")&","&D5&","&E5 -> Vanilla_Argonian03,1,1
A6: Vanilla | B6: HairArgonianFemale04,HairArgonianMale04 | C6: Vanilla - Argonian 04 | D6: 1 | E6: 1 | F6: Uvi_Wig_Spell_VHRU_Argonian04 | I6: Argonian_Female, Argonian_Male | J6: VHR,VHRWU | L6: =SUBSTITUTE(SUBSTITUTE(SUBSTITUTE(SUBSTITUTE(SUBSTITUTE(C6," ",""),"'",""),"(",""),")",""),"-","_")&","&D6&","&E6 -> Vanilla_Argonian04,1,1
A7: Vanilla | B7: HairArgonianFemale05,HairArgonianMale05 | C7: Vanilla - Argonian 05 | D7: 1 | E7: 1 | F7: Uvi_Wig_Spell_VHRU_Argonian05 | I7: Argonian_Female, Argonian_Male | J7: VHR,VHRWU | L7: =SUBSTITUTE(SUBSTITUTE(SUBSTITUTE(SUBSTITUTE(SUBSTITUTE(C7," ",""),"'",""),"(",""),")",""),"-","_")&","&D7&","&E7 -> Vanilla_Argonian05,1,1
A8: Vanilla | B8: HairArgonianFemale06,HairArgonianMale06 | C8: Vanilla - Argonian 06 | D8: 1 | E8: 1 | F8: Uvi_Wig_Spell_VHRU_Argonian06 | I8: Argonian_Female, Argonian_Male | J8: VHR,VHRWU | L8: =SUBSTITUTE(SUBSTITUTE(SUBSTITUTE(SUBSTITUTE(SUBSTITUTE(C8," ",""),"'",""),"(",""),")",""),"-","_")&","&D8&","&E8 -> Vanilla_Argonian06,1,1
A9: Vanilla | B9: HairArgonianFemale07,HairArgonianMale07 | C9: Vanilla - Argonian 07 | D9: 1 | E9: 1 | F9: Uvi_Wig_Spell_VHRU_Argonian07 | I9: Argonian_Female, Argonian_Male | J9: VHR,VHRWU | L9: =SUBSTITUTE(SUBSTITUTE(SUBSTITUTE(SUBSTITUTE(SUBSTITUTE(C9," ",""),"'",""),"(",""),")",""),"-","_")&","&D9&","&E9 -> Vanilla_Argonian07,1,1
A10: Vanilla | B10: HairArgonianFemale08,HairArgonianMale08 | C10: Vanilla - Argonian 08 | D10: 1 | E10: 1 | F10: Uvi_Wig_Spell_VHRU_Argonian08 | I10: Argonian_Female, Argonian_Male | J10: VHR,VHRWU | L10: =SUBSTITUTE(SUBSTITUTE(SUBSTITUTE(SUBSTITUTE(SUBSTITUTE(C10," ",""),"'",""),"(",""),")",""),"-","_")&","&D10&","&E10 -> Vanilla_Argonian08,1,1
A11: Vanilla | B11: HairArgonianFemale09,HairArgonianMale09 | C11: Vanilla - Argonian 09 | D11: 1 | E11: 1 | F11: Uvi_Wig_Spell_VHRU_Argonian09 | I11: Argonian_Female, Argonian_Male | J11: VHR,VHRWU | L11: =SUBSTITUTE(SUBSTITUTE(SUBSTITUTE(SUBSTITUTE(SUBSTITUTE(C11," ",""),"'",""),"(",""),")",""),"-","_")&","&D11&","&E11 -> Vanilla_Argonian09,1,1
A12: Vanilla | B12: HairArgonianFemale10,HairArgonianMale10 | C12: Vanilla - Argonian 10 | D12: 1 | E12: 1 | F12: Uvi_Wig_Spell_VHRU_Argonian10 | I12: Argonian_Female, Argonian_Male | J12: VHR,VHRWU | L12: =SUBSTITUTE(SUBSTITUTE(SUBSTITUTE(SUBSTITUTE(SUBSTITUTE(C12," ",""),"'",""),"(",""),")",""),"-","_")&","&D12&","&E12 -> Vanilla_Argonian10,1,1
A13: Vanilla | B13: HairArgonianFemale11 | C13: Vanilla - Argonian 11 | D13: 1 | E13: 1 | F13: Uvi_Wig_Spell_VHRU_Argonian11 | I13: Argonian_Female | J13: VHR,VHRWU | L13: =SUBSTITUTE(SUBSTITUTE(SUBSTITUTE(SUBSTITUTE(SUBSTITUTE(C13," ",""),"'",""),"(",""),")",""),"-","_")&","&D13&","&E13 -> Vanilla_Argonian11,1,1
... A112: Vanilla | B112: HairMaleDarkElf06 | C112: Vanilla - Widow's Peak Windswept | D112: 1 | E112: 1 | F112: Uvi_Wig_Spell_VHRU_WidowsPeakWindswept | I112: Human_Female, Human_Male, Elf_Female, Elf_Male, Orc_Female, Orc_Male, Khajiit_Female, Khajiit_Male | J112: VHR,VHRWU | L112: =SUBSTITUTE(SUBSTITUTE(SUBSTITUTE(SUBSTITUTE(SUBSTITUTE(C112," ",""),"'",""),"(",""),")",""),"-","_")&","&D112&","&E112 -> Vanilla_WidowsPeakWindswept,1,1
A113: Dint Hair Pack 02 | C113: Dint Hair Pack 02 - 1 | D113: 3 | E113: =D113 -> 3 | F113: Uvi_Wig_Spell_Dint02_01 | G113: Elf, Human, Orc | H113: Female | I113: =IFERROR(__xludf.DUMMYFUNCTION("IF(OR(TRIM(G113)="""",TRIM(H113)=""""),"""",TEXTJOIN("", "",TRUE,ARRAYFORMULA(TRANSPOSE(TRIM(SPLIT(G113,"","")))&""_""&TRIM(SPLIT(H113,"","")))))"),"Elf_Female, Human_Female, Orc_Female") -> Elf_Female, Human_Female, Orc_Female | J113: Dint02 | L113: =SUBSTITUTE(SUBSTITUTE(SUBSTITUTE(SUBSTITUTE(SUBSTITUTE(C113," ",""),"'",""),"(",""),")",""),"-","_")&","&D113&","&E113 -> DintHairPack02_1,3,3
A114: Dint Hair Pack 02 | C114: Dint Hair Pack 02 - 2 | D114: 3 | E114: =D114 -> 3 | F114: Uvi_Wig_Spell_Dint02_02 | G114: Elf, Human, Orc | H114: Female | I114: =IFERROR(__xludf.DUMMYFUNCTION("IF(OR(TRIM(G114)="""",TRIM(H114)=""""),"""",TEXTJOIN("", "",TRUE,ARRAYFORMULA(TRANSPOSE(TRIM(SPLIT(G114,"","")))&""_""&TRIM(SPLIT(H114,"","")))))"),"Elf_Female, Human_Female, Orc_Female") -> Elf_Female, Human_Female, Orc_Female | J114: Dint02 | L114: =SUBSTITUTE(SUBSTITUTE(SUBSTITUTE(SUBSTITUTE(SUBSTITUTE(C114," ",""),"'",""),"(",""),")",""),"-","_")&","&D114&","&E114 -> DintHairPack02_2,3,3
A115: Dint Hair Pack 02 | C115: Dint Hair Pack 02 - 3 | D115: 3 | E115: =D115 -> 3 | F115: Uvi_Wig_Spell_Dint02_03 | G115: Elf, Human, Orc | H115: Male, Female | I115: =IFERROR(__xludf.DUMMYFUNCTION("IF(OR(TRIM(G115)="""",TRIM(H115)=""""),"""",TEXTJOIN("", "",TRUE,ARRAYFORMULA(TRANSPOSE(TRIM(SPLIT(G115,"","")))&""_""&TRIM(SPLIT(H115,"","")))))"),"Elf_Male, Elf_Female, Human_Male, Human_Female, Orc_Male, Orc_Female") -> Elf_Male, Elf_Female, Human_Male, Human_Female, Orc_Male, Orc_Female | J115: Dint02 | L115: =SUBSTITUTE(SUBSTITUTE(SUBSTITUTE(SUBSTITUTE(SUBSTITUTE(C115," ",""),"'",""),"(",""),")",""),"-","_")&","&D115&","&E115 -> DintHairPack02_3,3,3
A116: Dint Hair Pack 02 | C116: Dint Hair Pack 02 - 3 Long | D116: 4 | E116: =D116 -> 4 | F116: Uvi_Wig_Spell_Dint02_03Long | G116: Elf, Human, Orc | H116: Female | I116: =IFERROR(__xludf.DUMMYFUNCTION("IF(OR(TRIM(G116)="""",TRIM(H116)=""""),"""",TEXTJOIN("", "",TRUE,ARRAYFORMULA(TRANSPOSE(TRIM(SPLIT(G116,"","")))&""_""&TRIM(SPLIT(H116,"","")))))"),"Elf_Female, Human_Female, Orc_Female") -> Elf_Female, Human_Female, Orc_Female | J116: Dint02 | L116: =SUBSTITUTE(SUBSTITUTE(SUBSTITUTE(SUBSTITUTE(SUBSTITUTE(C116," ",""),"'",""),"(",""),")",""),"-","_")&","&D116&","&E116 -> DintHairPack02_3Long,4,4
A117: Dint Hair Pack 02 | C117: Dint Hair Pack 02 - 4 | D117: 3 | E117: =D117 -> 3 | F117: Uvi_Wig_Spell_Dint02_04 | G117: Elf, Human, Orc | H117: Male, Female | I117: =IFERROR(__xludf.DUMMYFUNCTION("IF(OR(TRIM(G117)="""",TRIM(H117)=""""),"""",TEXTJOIN("", "",TRUE,ARRAYFORMULA(TRANSPOSE(TRIM(SPLIT(G117,"","")))&""_""&TRIM(SPLIT(H117,"","")))))"),"Elf_Male, Elf_Female, Human_Male, Human_Female, Orc_Male, Orc_Female") -> Elf_Male, Elf_Female, Human_Male, Human_Female, Orc_Male, Orc_Female | J117: Dint02 | L117: =SUBSTITUTE(SUBSTITUTE(SUBSTITUTE(SUBSTITUTE(SUBSTITUTE(C117," ",""),"'",""),"(",""),")",""),"-","_")&","&D117&","&E117 -> DintHairPack02_4,3,3
A118: Dint Hair Pack 02 | C118: Dint Hair Pack 02 - 5 | D118: 3 | E118: 4 | F118: Uvi_Wig_Spell_Dint02_05 | G118: Elf, Human, Orc | H118: Male, Female | I118: =IFERROR(__xludf.DUMMYFUNCTION("IF(OR(TRIM(G118)="""",TRIM(H118)=""""),"""",TEXTJOIN("", "",TRUE,ARRAYFORMULA(TRANSPOSE(TRIM(SPLIT(G118,"","")))&""_""&TRIM(SPLIT(H118,"","")))))"),"Elf_Male, Elf_Female, Human_Male, Human_Female, Orc_Male, Orc_Female") -> Elf_Male, Elf_Female, Human_Male, Human_Female, Orc_Male, Orc_Female | J118: Dint02 | L118: =SUBSTITUTE(SUBSTITUTE(SUBSTITUTE(SUBSTITUTE(SUBSTITUTE(C118," ",""),"'",""),"(",""),")",""),"-","_")&","&D118&","&E118 -> DintHairPack02_5,3,4
A119: Dint Hair Pack 02 | C119: Dint Hair Pack 02 - 6 | D119: 1 | E119: =D119 -> 1 | F119: Uvi_Wig_Spell_Dint02_06 | G119: Elf, Human, Orc | H119: Male, Female | I119: =IFERROR(__xludf.DUMMYFUNCTION("IF(OR(TRIM(G119)="""",TRIM(H119)=""""),"""",TEXTJOIN("", "",TRUE,ARRAYFORMULA(TRANSPOSE(TRIM(SPLIT(G119,"","")))&""_""&TRIM(SPLIT(H119,"","")))))"),"Elf_Male, Elf_Female, Human_Male, Human_Female, Orc_Male, Orc_Female") -> Elf_Male, Elf_Female, Human_Male, Human_Female, Orc_Male, Orc_Female | J119: Dint02 | L119: =SUBSTITUTE(SUBSTITUTE(SUBSTITUTE(SUBSTITUTE(SUBSTITUTE(C119," ",""),"'",""),"(",""),")",""),"-","_")&","&D119&","&E119 -> DintHairPack02_6,1,1
A120: Dint Hair Pack 02 | C120: Dint Hair Pack 02 - 7 | D120: 3 | E120: 4 | F120: Uvi_Wig_Spell_Dint02_07 | G120: Elf, Human, Orc | H120: Female | I120: =IFERROR(__xludf.DUMMYFUNCTION("IF(OR(TRIM(G120)="""",TRIM(H120)=""""),"""",TEXTJOIN("", "",TRUE,ARRAYFORMULA(TRANSPOSE(TRIM(SPLIT(G120,"","")))&""_""&TRIM(SPLIT(H120,"","")))))"),"Elf_Female, Human_Female, Orc_Female") -> Elf_Female, Human_Female, Orc_Female | J120: Dint02 | L120: =SUBSTITUTE(SUBSTITUTE(SUBSTITUTE(SUBSTITUTE(SUBSTITUTE(C120," ",""),"'",""),"(",""),")",""),"-","_")&","&D120&","&E120 -> DintHairPack02_7,3,4
A121: Dint Hair Pack 02 | C121: Dint Hair Pack 02 - 8 | D121: 3 | E121: 3 | F121: Uvi_Wig_Spell_Dint02_08 | G121: Elf, Human, Orc | H121: Male, Female | I121: =IFERROR(__xludf.DUMMYFUNCTION("IF(OR(TRIM(G121)="""",TRIM(H121)=""""),"""",TEXTJOIN("", "",TRUE,ARRAYFORMULA(TRANSPOSE(TRIM(SPLIT(G121,"","")))&""_""&TRIM(SPLIT(H121,"","")))))"),"Elf_Male, Elf_Female, Human_Male, Human_Female, Orc_Male, Orc_Female") -> Elf_Male, Elf_Female, Human_Male, Human_Female, Orc_Male, Orc_Female | J121: Dint02 | L121: =SUBSTITUTE(SUBSTITUTE(SUBSTITUTE(SUBSTITUTE(SUBSTITUTE(C121," ",""),"'",""),"(",""),")",""),"-","_")&","&D121&","&E121 -> DintHairPack02_8,3,3
A122: Dint Hair Pack 02 | C122: Dint Hair Pack 02 - 9 | D122: 1 | E122: 2 | F122: Uvi_Wig_Spell_Dint02_09 | G122: Elf, Human, Orc | H122: Female | I122: =IFERROR(__xludf.DUMMYFUNCTION("IF(OR(TRIM(G122)="""",TRIM(H122)=""""),"""",TEXTJOIN("", "",TRUE,ARRAYFORMULA(TRANSPOSE(TRIM(SPLIT(G122,"","")))&""_""&TRIM(SPLIT(H122,"","")))))"),"Elf_Female, Human_Female, Orc_Female") -> Elf_Female, Human_Female, Orc_Female | J122: Dint02 | L122: =SUBSTITUTE(SUBSTITUTE(SUBSTITUTE(SUBSTITUTE(SUBSTITUTE(C122," ",""),"'",""),"(",""),")",""),"-","_")&","&D122&","&E122 -> DintHairPack02_9,1,2
A123: Dint Hair Pack 02 | C123: Dint Hair Pack 02 - 10 | D123: 3 | E123: 3 | F123: Uvi_Wig_Spell_Dint02_10 | G123: Elf, Human, Orc | H123: Male, Female | I123: =IFERROR(__xludf.DUMMYFUNCTION("IF(OR(TRIM(G123)="""",TRIM(H123)=""""),"""",TEXTJOIN("", "",TRUE,ARRAYFORMULA(TRANSPOSE(TRIM(SPLIT(G123,"","")))&""_""&TRIM(SPLIT(H123,"","")))))"),"Elf_Male, Elf_Female, Human_Male, Human_Female, Orc_Male, Orc_Female") -> Elf_Male, Elf_Female, Human_Male, Human_Female, Orc_Male, Orc_Female | J123: Dint02 | L123: =SUBSTITUTE(SUBSTITUTE(SUBSTITUTE(SUBSTITUTE(SUBSTITUTE(C123," ",""),"'",""),"(",""),")",""),"-","_")&","&D123&","&E123 -> DintHairPack02_10,3,3
A124: Dint Hair Pack 02 | C124: Dint Hair Pack 02 - 11 | D124: 1 | E124: 4 | F124: Uvi_Wig_Spell_Dint02_11 | G124: Elf, Human, Orc | H124: Female | I124: =IFERROR(__xludf.DUMMYFUNCTION("IF(OR(TRIM(G124)="""",TRIM(H124)=""""),"""",TEXTJOIN("", "",TRUE,ARRAYFORMULA(TRANSPOSE(TRIM(SPLIT(G124,"","")))&""_""&TRIM(SPLIT(H124,"","")))))"),"Elf_Female, Human_Female, Orc_Female") -> Elf_Female, Human_Female, Orc_Female | J124: Dint02 | L124: =SUBSTITUTE(SUBSTITUTE(SUBSTITUTE(SUBSTITUTE(SUBSTITUTE(C124," ",""),"'",""),"(",""),")",""),"-","_")&","&D124&","&E124 -> DintHairPack02_11,1,4
A125: Dint Hair Pack 02 | C125: Dint Hair Pack 02 - 12 | D125: 2 | E125: =D125 -> 2 | F125: Uvi_Wig_Spell_Dint02_12 | G125: Elf, Human, Orc | H125: Female | I125: =IFERROR(__xludf.DUMMYFUNCTION("IF(OR(TRIM(G125)="""",TRIM(H125)=""""),"""",TEXTJOIN("", "",TRUE,ARRAYFORMULA(TRANSPOSE(TRIM(SPLIT(G125,"","")))&""_""&TRIM(SPLIT(H125,"","")))))"),"Elf_Female, Human_Female, Orc_Female") -> Elf_Female, Human_Female, Orc_Female | J125: Dint02 | L125: =SUBSTITUTE(SUBSTITUTE(SUBSTITUTE(SUBSTITUTE(SUBSTITUTE(C125," ",""),"'",""),"(",""),")",""),"-","_")&","&D125&","&E125 -> DintHairPack02_12,2,2
A126: Dint Hair Pack 02 | C126: Dint Hair Pack 02 - 13 | D126: 2 | E126: =D126 -> 2 | F126: Uvi_Wig_Spell_Dint02_13 | G126: Elf, Human, Orc | H126: Female | I126: =IFERROR(__xludf.DUMMYFUNCTION("IF(OR(TRIM(G126)="""",TRIM(H126)=""""),"""",TEXTJOIN("", "",TRUE,ARRAYFORMULA(TRANSPOSE(TRIM(SPLIT(G126,"","")))&""_""&TRIM(SPLIT(H126,"","")))))"),"Elf_Female, Human_Female, Orc_Female") -> Elf_Female, Human_Female, Orc_Female | J126: Dint02 | L126: =SUBSTITUTE(SUBSTITUTE(SUBSTITUTE(SUBSTITUTE(SUBSTITUTE(C126," ",""),"'",""),"(",""),")",""),"-","_")&","&D126&","&E126 -> DintHairPack02_13,2,2
A127: Dint Hair Pack 02 | C127: Dint Hair Pack 02 - 14 | D127: 2 | E127: =D127 -> 2 | F127: Uvi_Wig_Spell_Dint02_14 | G127: Elf, Human, Orc | H127: Female | I127: =IFERROR(__xludf.DUMMYFUNCTION("IF(OR(TRIM(G127)="""",TRIM(H127)=""""),"""",TEXTJOIN("", "",TRUE,ARRAYFORMULA(TRANSPOSE(TRIM(SPLIT(G127,"","")))&""_""&TRIM(SPLIT(H127,"","")))))"),"Elf_Female, Human_Female, Orc_Female") -> Elf_Female, Human_Female, Orc_Female | J127: Dint02 | L127: =SUBSTITUTE(SUBSTITUTE(SUBSTITUTE(SUBSTITUTE(SUBSTITUTE(C127," ",""),"'",""),"(",""),")",""),"-","_")&","&D127&","&E127 -> DintHairPack02_14,2,2
A128: Dint Hair Pack 02 | C128: Dint Hair Pack 02 - 15 | D128: 3 | E128: 4 | F128: Uvi_Wig_Spell_Dint02_15 | G128: Elf, Human, Orc | H128: Male, Female | I128: =IFERROR(__xludf.DUMMYFUNCTION("IF(OR(TRIM(G128)="""",TRIM(H128)=""""),"""",TEXTJOIN("", "",TRUE,ARRAYFORMULA(TRANSPOSE(TRIM(SPLIT(G128,"","")))&""_""&TRIM(SPLIT(H128,"","")))))"),"Elf_Male, Elf_Female, Human_Male, Human_Female, Orc_Male, Orc_Female") -> Elf_Male, Elf_Female, Human_Male, Human_Female, Orc_Male, Orc_Female | J128: Dint02 | L128: =SUBSTITUTE(SUBSTITUTE(SUBSTITUTE(SUBSTITUTE(SUBSTITUTE(C128," ",""),"'",""),"(",""),")",""),"-","_")&","&D128&","&E128 -> DintHairPack02_15,3,4
A129: Dint Hair Pack 02 | C129: Dint Hair Pack 02 - 16 | D129: 3 | E129: 4 | F129: Uvi_Wig_Spell_Dint02_16 | G129: Elf, Human, Orc | H129: Male, Female | I129: =IFERROR(__xludf.DUMMYFUNCTION("IF(OR(TRIM(G129)="""",TRIM(H129)=""""),"""",TEXTJOIN("", "",TRUE,ARRAYFORMULA(TRANSPOSE(TRIM(SPLIT(G129,"","")))&""_""&TRIM(SPLIT(H129,"","")))))"),"Elf_Male, Elf_Female, Human_Male, Human_Female, Orc_Male, Orc_Female") -> Elf_Male, Elf_Female, Human_Male, Human_Female, Orc_Male, Orc_Female | J129: Dint02 | L129: =SUBSTITUTE(SUBSTITUTE(SUBSTITUTE(SUBSTITUTE(SUBSTITUTE(C129," ",""),"'",""),"(",""),")",""),"-","_")&","&D129&","&E129 -> DintHairPack02_16,3,4
A130: Dint Hair Pack 02 | C130: Dint Hair Pack 02 - 17 | D130: 1 | E130: =D130 -> 1 | F130: Uvi_Wig_Spell_Dint02_17 | G130: Elf, Human, Orc | H130: Male, Female | I130: =IFERROR(__xludf.DUMMYFUNCTION("IF(OR(TRIM(G130)="""",TRIM(H130)=""""),"""",TEXTJOIN("", "",TRUE,ARRAYFORMULA(TRANSPOSE(TRIM(SPLIT(G130,"","")))&""_""&TRIM(SPLIT(H130,"","")))))"),"Elf_Male, Elf_Female, Human_Male, Human_Female, Orc_Male, Orc_Female") -> Elf_Male, Elf_Female, Human_Male, Human_Female, Orc_Male, Orc_Female | J130: Dint02 | L130: =SUBSTITUTE(SUBSTITUTE(SUBSTITUTE(SUBSTITUTE(SUBSTITUTE(C130," ",""),"'",""),"(",""),")",""),"-","_")&","&D130&","&E130 -> DintHairPack02_17,1,1
A131: Dint Hair Pack 02 | C131: Dint Hair Pack 02 - 18A | D131: 3 | E131: 4 | F131: Uvi_Wig_Spell_Dint02_18A | G131: Elf, Human, Orc | H131: Male, Female | I131: =IFERROR(__xludf.DUMMYFUNCTION("IF(OR(TRIM(G131)="""",TRIM(H131)=""""),"""",TEXTJOIN("", "",TRUE,ARRAYFORMULA(TRANSPOSE(TRIM(SPLIT(G131,"","")))&""_""&TRIM(SPLIT(H131,"","")))))"),"Elf_Male, Elf_Female, Human_Male, Human_Female, Orc_Male, Orc_Female") -> Elf_Male, Elf_Female, Human_Male, Human_Female, Orc_Male, Orc_Female | J131: Dint02 | L131: =SUBSTITUTE(SUBSTITUTE(SUBSTITUTE(SUBSTITUTE(SUBSTITUTE(C131," ",""),"'",""),"(",""),")",""),"-","_")&","&D131&","&E131 -> DintHairPack02_18A,3,4
A132: Dint Hair Pack 02 | C132: Dint Hair Pack 02 - 18B | D132: 2 | E132: 4 | F132: Uvi_Wig_Spell_Dint02_18B | G132: Elf, Human, Orc | H132: Male, Female | I132: =IFERROR(__xludf.DUMMYFUNCTION("IF(OR(TRIM(G132)="""",TRIM(H132)=""""),"""",TEXTJOIN("", "",TRUE,ARRAYFORMULA(TRANSPOSE(TRIM(SPLIT(G132,"","")))&""_""&TRIM(SPLIT(H132,"","")))))"),"Elf_Male, Elf_Female, Human_Male, Human_Female, Orc_Male, Orc_Female") -> Elf_Male, Elf_Female, Human_Male, Human_Female, Orc_Male, Orc_Female | J132: Dint02 | L132: =SUBSTITUTE(SUBSTITUTE(SUBSTITUTE(SUBSTITUTE(SUBSTITUTE(C132," ",""),"'",""),"(",""),")",""),"-","_")&","&D132&","&E132 -> DintHairPack02_18B,2,4
A133: Dint Hair Pack 02 | C133: Dint Hair Pack 02 - 18C | D133: 2 | E133: 4 | F133: Uvi_Wig_Spell_Dint02_18C | G133: Elf, Human, Orc | H133: Male, Female | I133: =IFERROR(__xludf.DUMMYFUNCTION("IF(OR(TRIM(G133)="""",TRIM(H133)=""""),"""",TEXTJOIN("", "",TRUE,ARRAYFORMULA(TRANSPOSE(TRIM(SPLIT(G133,"","")))&""_""&TRIM(SPLIT(H133,"","")))))"),"Elf_Male, Elf_Female, Human_Male, Human_Female, Orc_Male, Orc_Female") -> Elf_Male, Elf_Female, Human_Male, Human_Female, Orc_Male, Orc_Female | J133: Dint02 | L133: =SUBSTITUTE(SUBSTITUTE(SUBSTITUTE(SUBSTITUTE(SUBSTITUTE(C133," ",""),"'",""),"(",""),")",""),"-","_")&","&D133&","&E133 -> DintHairPack02_18C,2,4
A134: Dint Hair Pack 02 | C134: Dint Hair Pack 02 - 19 | D134: 2 | E134: 3 | F134: Uvi_Wig_Spell_Dint02_19 | G134: Elf, Human, Orc | H134: Male, Female | I134: =IFERROR(__xludf.DUMMYFUNCTION("IF(OR(TRIM(G134)="""",TRIM(H134)=""""),"""",TEXTJOIN("", "",TRUE,ARRAYFORMULA(TRANSPOSE(TRIM(SPLIT(G134,"","")))&""_""&TRIM(SPLIT(H134,"","")))))"),"Elf_Male, Elf_Female, Human_Male, Human_Female, Orc_Male, Orc_Female") -> Elf_Male, Elf_Female, Human_Male, Human_Female, Orc_Male, Orc_Female | J134: Dint02 | L134: =SUBSTITUTE(SUBSTITUTE(SUBSTITUTE(SUBSTITUTE(SUBSTITUTE(C134," ",""),"'",""),"(",""),")",""),"-","_")&","&D134&","&E134 -> DintHairPack02_19,2,3
A135: Dint Hair Pack 02 | C135: Dint Hair Pack 02 - 20 | D135: 3 | E135: 3 | F135: Uvi_Wig_Spell_Dint02_20 | G135: Elf, Human, Orc | H135: Male, Female | I135: =IFERROR(__xludf.DUMMYFUNCTION("IF(OR(TRIM(G135)="""",TRIM(H135)=""""),"""",TEXTJOIN("", "",TRUE,ARRAYFORMULA(TRANSPOSE(TRIM(SPLIT(G135,"","")))&""_""&TRIM(SPLIT(H135,"","")))))"),"Elf_Male, Elf_Female, Human_Male, Human_Female, Orc_Male, Orc_Female") -> Elf_Male, Elf_Female, Human_Male, Human_Female, Orc_Male, Orc_Female | J135: Dint02 | L135: =SUBSTITUTE(SUBSTITUTE(SUBSTITUTE(SUBSTITUTE(SUBSTITUTE(C135," ",""),"'",""),"(",""),")",""),"-","_")&","&D135&","&E135 -> DintHairPack02_20,3,3
A136: Dint Hair Pack 02 | C136: Dint Hair Pack 02 - 21 | D136: 2 | E136: =D136 -> 2 | F136: Uvi_Wig_Spell_Dint02_21 | G136: Elf, Human, Orc | H136: Male, Female | I136: =IFERROR(__xludf.DUMMYFUNCTION("IF(OR(TRIM(G136)="""",TRIM(H136)=""""),"""",TEXTJOIN("", "",TRUE,ARRAYFORMULA(TRANSPOSE(TRIM(SPLIT(G136,"","")))&""_""&TRIM(SPLIT(H136,"","")))))"),"Elf_Male, Elf_Female, Human_Male, Human_Female, Orc_Male, Orc_Female") -> Elf_Male, Elf_Female, Human_Male, Human_Female, Orc_Male, Orc_Female | J136: Dint02 | L136: =SUBSTITUTE(SUBSTITUTE(SUBSTITUTE(SUBSTITUTE(SUBSTITUTE(C136," ",""),"'",""),"(",""),")",""),"-","_")&","&D136&","&E136 -> DintHairPack02_21,2,2
A137: Dint Hair Pack 02 | C137: Dint Hair Pack 02 - 22 | D137: 2 | E137: 4 | F137: Uvi_Wig_Spell_Dint02_22 | G137: Elf, Human, Orc | H137: Male, Female | I137: =IFERROR(__xludf.DUMMYFUNCTION("IF(OR(TRIM(G137)="""",TRIM(H137)=""""),"""",TEXTJOIN("", "",TRUE,ARRAYFORMULA(TRANSPOSE(TRIM(SPLIT(G137,"","")))&""_""&TRIM(SPLIT(H137,"","")))))"),"Elf_Male, Elf_Female, Human_Male, Human_Female, Orc_Male, Orc_Female") -> Elf_Male, Elf_Female, Human_Male, Human_Female, Orc_Male, Orc_Female | J137: Dint02 | L137: =SUBSTITUTE(SUBSTITUTE(SUBSTITUTE(SUBSTITUTE(SUBSTITUTE(C137," ",""),"'",""),"(",""),")",""),"-","_")&","&D137&","&E137 -> DintHairPack02_22,2,4
A138: Dint Hair Pack 02 | C138: Dint Hair Pack 02 - 23 | D138: 2 | E138: 2 | F138: Uvi_Wig_Spell_Dint02_23 | G138: Elf, Human, Orc | H138: Male, Female | I138: =IFERROR(__xludf.DUMMYFUNCTION("IF(OR(TRIM(G138)="""",TRIM(H138)=""""),"""",TEXTJOIN("", "",TRUE,ARRAYFORMULA(TRANSPOSE(TRIM(SPLIT(G138,"","")))&""_""&TRIM(SPLIT(H138,"","")))))"),"Elf_Male, Elf_Female, Human_Male, Human_Female, Orc_Male, Orc_Female") -> Elf_Male, Elf_Female, Human_Male, Human_Female, Orc_Male, Orc_Female | J138: Dint02 | L138: =SUBSTITUTE(SUBSTITUTE(SUBSTITUTE(SUBSTITUTE(SUBSTITUTE(C138," ",""),"'",""),"(",""),")",""),"-","_")&","&D138&","&E138 -> DintHairPack02_23,2,2
...

Sheet Hairstyle Requirements
A1: RequirementID | B1: Link Text | C1: Link
A2: VHR | B2: Vanilla Hair Remake (Main file) | C2: https://www.nexusmods.com/skyrimspecialedition/mods/63979
A3: VHRWU | B3: Vanilla Hair Remake Wigs Unlocked | C3: https://www.nexusmods.com/skyrimspecialedition/mods/187429
A4: Dint02 | B4: Dint Hair Pack 02 | C4: https://www.patreon.com/dint999/posts/hairpack02-hdt-1-29917266
A5: Mod_SMP_Hair | B5: Modular SMP Hairstyles | C5: https://www.nexusmods.com/skyrimspecialedition/mods/93608
A6: Mod_SMP_Wig | B6: Modular SMP Wigs | C6: https://www.nexusmods.com/skyrimspecialedition/mods/180029
A7: Kora1 | B7: Koralina's Hair Collection 1 (Wig file) | C7: https://www.nexusmods.com/skyrimspecialedition/mods/114769
A8: Kora2 | B8: Koralina's Hair Collection 2 (Wig file) | C8: https://www.nexusmods.com/skyrimspecialedition/mods/172939
A9: Fuse_Aldo | B9: Fuse Hair Collection - Aldo | C9: https://www.patreon.com/posts/68250938?collection=209996
A10: Fuse_Alucard | B10: Fuse Hair Collection - Alucard | C10: https://www.patreon.com/posts/98291872?collection=209996
A11: Fuse_Amber | B11: Fuse Hair Collection - Amber | C11: https://www.patreon.com/posts/76570894?collection=209996
A12: Fuse_BraidedHair | B12: Fuse Hair Collection - Braided Hairstyles | C12: https://www.patreon.com/posts/64262256?collection=209996
... A29: Xing_Misc | B29: Misc Improvements | C29: https://www.nexusmods.com/skyrimspecialedition/mods/184585

Sheet Race Default Hairstyles
A1: Race | B1: Race Type | C1: Default Male Hair | D1: Default Female Hair
A2: Argonian | B2: Argonian
A3: ArgonianVampire | B3: Argonian
A4: Breton | B4: Human | C4: HairMaleImperial1 | D4: HairFemaleNord05
A5: BretonChild | B5: HumanChild | C5: HairMaleImperialChild01 | D5: HairFemaleNordChild01
A6: BretonChildVampire | B6: HumanChild | C6: HairMaleImperialChild01 | D6: HairFemaleNordChild01
A7: BretonVampire | B7: Human
A8: DA13Afflicted | B8: Human | C8: HairMaleNord01 | D8: HairFemaleNord01
A9: DarkElf | B9: Elf | C9: HairMaleDarkElf01 | D9: HairFemaleDarkElf01
A10: DarkElfVampire | B10: Elf
A11: Elder | B11: Human | D11: HairFemaleElder02
A12: ElderVampire | B12: Human | D12: HairFemaleElder02
A13: HighElf | B13: Elf | C13: HairMaleDarkElf01 | D13: HairFemaleDarkElf01
A14: HighElfVampire | B14: Elf
A15: Imperial | B15: Human | C15: HairMaleImperial1 | D15: HairFemaleNord01
A16: ImperialChild | B16: HumanChild | C16: HairMaleImperialChild01 | D16: HairFemaleNordChild02
A17: ImperialVampire | B17: Human
A18: Khajiit | B18: Khajiit
A19: KhajiitVampire | B19: Khajiit
A20: Nord | B20: Human | C20: HairMaleNord10 | D20: HairFemaleNord04
A21: NordAstrid | B21: Human | C21: HairMaleNord10 | D21: HairFemaleNord05
A22: NordChild | B22: HumanChild | C22: HairMaleNordChild01 | D22: HairFemaleNordChild01
A23: NordVampire | B23: Human
A24: Orc | B24: Orc | C24: HairMaleOrc01
A25: OrcVampire | B25: Orc
A26: Redguard | B26: Human | C26: HairMaleRedguard2 | D26: HairFemaleRedguard01
A27: RedguardChild | B27: HumanChild | C27: HairMaleRedguardChild01 | D27: HairFemaleRedguardChild01
A28: RedguardVampire | B28: Human
A29: WoodElf | B29: Elf | C29: HairMaleDarkElf06 | D29: HairFemaleDarkElf03
A30: WoodElfVampire | B30: Elf
A31: SnowElf | B31: Elf | C31: HairMaleSnowElf01 | D31: HairFemaleDarkElf01
A32: DLC1Nord | B32: Human | C32: HairMaleNord10 | D32: DLC1HairFemaleSeranaHuman
A33: DLC2Miraak | B33: Human | C33: HairMaleNord10 | D33: HairFemaleNord04

Sheet Screenshot Creation
A1: Hairstyle Category | B1: Hair Spell IDs | C1: Screenshot Name
A2: Human_Male | B2: =IFERROR(__xludf.DUMMYFUNCTION("FILTER(Hairstyles!$F:$F, ISNUMBER(SEARCH(A$2, Hairstyles!$I:$I)))"),"Uvi_Wig_Spell_VHRU_BaldCap") -> Uvi_Wig_Spell_VHRU_BaldCap | C2: =IFERROR(__xludf.DUMMYFUNCTION("IF($B2="""","""",SUBSTITUTE(SUBSTITUTE(SUBSTITUTE(SUBSTITUTE(INDEX(Hairstyles!$A:$A,MATCH($B2,Hairstyles!$F:$F,0)),"" "",""""),""'"",""""),""("",""""),"")"","""")&""\""&INDEX(SPLIT($A$2,""_""),1)&""\""&INDEX(SPLIT($A$2,""_""),2)&""\""&SUBSTITUTE(SUBSTITUT"&"E(SUBSTITUTE(SUBSTITUTE(SUBSTITUTE(INDEX(Hairstyles!$C:$C,MATCH($B2,Hairstyles!$F:$F,0)),"" "",""""),""'"",""""),""("",""""),"")"",""""),""-"",""_"")&""_""&$A$2)"),"Vanilla\Human\Male\Vanilla_Bald_Human_Male") -> Vanilla\Human\Male\Vanilla_Bald_Human_Male
B3: =IFERROR(__xludf.DUMMYFUNCTION("""COMPUTED_VALUE"""),"Uvi_Wig_Spell_VHRU_AfroLarge") -> Uvi_Wig_Spell_VHRU_AfroLarge | C3: =IFERROR(__xludf.DUMMYFUNCTION("IF($B3="""","""",SUBSTITUTE(SUBSTITUTE(SUBSTITUTE(SUBSTITUTE(INDEX(Hairstyles!$A:$A,MATCH($B3,Hairstyles!$F:$F,0)),"" "",""""),""'"",""""),""("",""""),"")"","""")&""\""&INDEX(SPLIT($A$2,""_""),1)&""\""&INDEX(SPLIT($A$2,""_""),2)&""\""&SUBSTITUTE(SUBSTITUT"&"E(SUBSTITUTE(SUBSTITUTE(SUBSTITUTE(INDEX(Hairstyles!$C:$C,MATCH($B3,Hairstyles!$F:$F,0)),"" "",""""),""'"",""""),""("",""""),"")"",""""),""-"",""_"")&""_""&$A$2)"),"Vanilla\Human\Male\Vanilla_AfroLarge_Human_Male") -> Vanilla\Human\Male\Vanilla_AfroLarge_Human_Male
B4: =IFERROR(__xludf.DUMMYFUNCTION("""COMPUTED_VALUE"""),"Uvi_Wig_Spell_VHRU_AfroSmall") -> Uvi_Wig_Spell_VHRU_AfroSmall | C4: =IFERROR(__xludf.DUMMYFUNCTION("IF($B4="""","""",SUBSTITUTE(SUBSTITUTE(SUBSTITUTE(SUBSTITUTE(INDEX(Hairstyles!$A:$A,MATCH($B4,Hairstyles!$F:$F,0)),"" "",""""),""'"",""""),""("",""""),"")"","""")&""\""&INDEX(SPLIT($A$2,""_""),1)&""\""&INDEX(SPLIT($A$2,""_""),2)&""\""&SUBSTITUTE(SUBSTITUT"&"E(SUBSTITUTE(SUBSTITUTE(SUBSTITUTE(INDEX(Hairstyles!$C:$C,MATCH($B4,Hairstyles!$F:$F,0)),"" "",""""),""'"",""""),""("",""""),"")"",""""),""-"",""_"")&""_""&$A$2)"),"Vanilla\Human\Male\Vanilla_AfroSmall_Human_Male") -> Vanilla\Human\Male\Vanilla_AfroSmall_Human_Male
B5: =IFERROR(__xludf.DUMMYFUNCTION("""COMPUTED_VALUE"""),"Uvi_Wig_Spell_VHRU_BaldingBun") -> Uvi_Wig_Spell_VHRU_BaldingBun | C5: =IFERROR(__xludf.DUMMYFUNCTION("IF($B5="""","""",SUBSTITUTE(SUBSTITUTE(SUBSTITUTE(SUBSTITUTE(INDEX(Hairstyles!$A:$A,MATCH($B5,Hairstyles!$F:$F,0)),"" "",""""),""'"",""""),""("",""""),"")"","""")&""\""&INDEX(SPLIT($A$2,""_""),1)&""\""&INDEX(SPLIT($A$2,""_""),2)&""\""&SUBSTITUTE(SUBSTITUT"&"E(SUBSTITUTE(SUBSTITUTE(SUBSTITUTE(INDEX(Hairstyles!$C:$C,MATCH($B5,Hairstyles!$F:$F,0)),"" "",""""),""'"",""""),""("",""""),"")"",""""),""-"",""_"")&""_""&$A$2)"),"Vanilla\Human\Male\Vanilla_BaldingBun_Human_Male") -> Vanilla\Human\Male\Vanilla_BaldingBun_Human_Male
B6: =IFERROR(__xludf.DUMMYFUNCTION("""COMPUTED_VALUE"""),"Uvi_Wig_Spell_VHRU_BaldingLong") -> Uvi_Wig_Spell_VHRU_BaldingLong | C6: =IFERROR(__xludf.DUMMYFUNCTION("IF($B6="""","""",SUBSTITUTE(SUBSTITUTE(SUBSTITUTE(SUBSTITUTE(INDEX(Hairstyles!$A:$A,MATCH($B6,Hairstyles!$F:$F,0)),"" "",""""),""'"",""""),""("",""""),"")"","""")&""\""&INDEX(SPLIT($A$2,""_""),1)&""\""&INDEX(SPLIT($A$2,""_""),2)&""\""&SUBSTITUTE(SUBSTITUT"&"E(SUBSTITUTE(SUBSTITUTE(SUBSTITUTE(INDEX(Hairstyles!$C:$C,MATCH($B6,Hairstyles!$F:$F,0)),"" "",""""),""'"",""""),""("",""""),"")"",""""),""-"",""_"")&""_""&$A$2)"),"Vanilla\Human\Male\Vanilla_BaldingLong_Human_Male") -> Vanilla\Human\Male\Vanilla_BaldingLong_Human_Male
B7: =IFERROR(__xludf.DUMMYFUNCTION("""COMPUTED_VALUE"""),"Uvi_Wig_Spell_VHRU_BaldingPonytailLong") -> Uvi_Wig_Spell_VHRU_BaldingPonytailLong | C7: =IFERROR(__xludf.DUMMYFUNCTION("IF($B7="""","""",SUBSTITUTE(SUBSTITUTE(SUBSTITUTE(SUBSTITUTE(INDEX(Hairstyles!$A:$A,MATCH($B7,Hairstyles!$F:$F,0)),"" "",""""),""'"",""""),""("",""""),"")"","""")&""\""&INDEX(SPLIT($A$2,""_""),1)&""\""&INDEX(SPLIT($A$2,""_""),2)&""\""&SUBSTITUTE(SUBSTITUT"&"E(SUBSTITUTE(SUBSTITUTE(SUBSTITUTE(INDEX(Hairstyles!$C:$C,MATCH($B7,Hairstyles!$F:$F,0)),"" "",""""),""'"",""""),""("",""""),"")"",""""),""-"",""_"")&""_""&$A$2)"),"Vanilla\Human\Male\Vanilla_BaldingPonytailLong_Human_Male") -> Vanilla\Human\Male\Vanilla_BaldingPonytailLong_Human_Male
B8: =IFERROR(__xludf.DUMMYFUNCTION("""COMPUTED_VALUE"""),"Uvi_Wig_Spell_VHRU_BaldingShort1") -> Uvi_Wig_Spell_VHRU_BaldingShort1 | C8: =IFERROR(__xludf.DUMMYFUNCTION("IF($B8="""","""",SUBSTITUTE(SUBSTITUTE(SUBSTITUTE(SUBSTITUTE(INDEX(Hairstyles!$A:$A,MATCH($B8,Hairstyles!$F:$F,0)),"" "",""""),""'"",""""),""("",""""),"")"","""")&""\""&INDEX(SPLIT($A$2,""_""),1)&""\""&INDEX(SPLIT($A$2,""_""),2)&""\""&SUBSTITUTE(SUBSTITUT"&"E(SUBSTITUTE(SUBSTITUTE(SUBSTITUTE(INDEX(Hairstyles!$C:$C,MATCH($B8,Hairstyles!$F:$F,0)),"" "",""""),""'"",""""),""("",""""),"")"",""""),""-"",""_"")&""_""&$A$2)"),"Vanilla\Human\Male\Vanilla_BaldingShort1_Human_Male") -> Vanilla\Human\Male\Vanilla_BaldingShort1_Human_Male
B9: =IFERROR(__xludf.DUMMYFUNCTION("""COMPUTED_VALUE"""),"Uvi_Wig_Spell_VHRU_BaldingShort2") -> Uvi_Wig_Spell_VHRU_BaldingShort2 | C9: =IFERROR(__xludf.DUMMYFUNCTION("IF($B9="""","""",SUBSTITUTE(SUBSTITUTE(SUBSTITUTE(SUBSTITUTE(INDEX(Hairstyles!$A:$A,MATCH($B9,Hairstyles!$F:$F,0)),"" "",""""),""'"",""""),""("",""""),"")"","""")&""\""&INDEX(SPLIT($A$2,""_""),1)&""\""&INDEX(SPLIT($A$2,""_""),2)&""\""&SUBSTITUTE(SUBSTITUT"&"E(SUBSTITUTE(SUBSTITUTE(SUBSTITUTE(INDEX(Hairstyles!$C:$C,MATCH($B9,Hairstyles!$F:$F,0)),"" "",""""),""'"",""""),""("",""""),"")"",""""),""-"",""_"")&""_""&$A$2)"),"Vanilla\Human\Male\Vanilla_BaldingShort2_Human_Male") -> Vanilla\Human\Male\Vanilla_BaldingShort2_Human_Male
B10: =IFERROR(__xludf.DUMMYFUNCTION("""COMPUTED_VALUE"""),"Uvi_Wig_Spell_VHRU_BaldingShort3") -> Uvi_Wig_Spell_VHRU_BaldingShort3 | C10: =IFERROR(__xludf.DUMMYFUNCTION("IF($B10="""","""",SUBSTITUTE(SUBSTITUTE(SUBSTITUTE(SUBSTITUTE(INDEX(Hairstyles!$A:$A,MATCH($B10,Hairstyles!$F:$F,0)),"" "",""""),""'"",""""),""("",""""),"")"","""")&""\""&INDEX(SPLIT($A$2,""_""),1)&""\""&INDEX(SPLIT($A$2,""_""),2)&""\""&SUBSTITUTE(SUBSTIT"&"UTE(SUBSTITUTE(SUBSTITUTE(SUBSTITUTE(INDEX(Hairstyles!$C:$C,MATCH($B10,Hairstyles!$F:$F,0)),"" "",""""),""'"",""""),""("",""""),"")"",""""),""-"",""_"")&""_""&$A$2)"),"Vanilla\Human\Male\Vanilla_BaldingShort3_Human_Male") -> Vanilla\Human\Male\Vanilla_BaldingShort3_Human_Male
B11: =IFERROR(__xludf.DUMMYFUNCTION("""COMPUTED_VALUE"""),"Uvi_Wig_Spell_VHRU_BaldingShort4") -> Uvi_Wig_Spell_VHRU_BaldingShort4 | C11: =IFERROR(__xludf.DUMMYFUNCTION("IF($B11="""","""",SUBSTITUTE(SUBSTITUTE(SUBSTITUTE(SUBSTITUTE(INDEX(Hairstyles!$A:$A,MATCH($B11,Hairstyles!$F:$F,0)),"" "",""""),""'"",""""),""("",""""),"")"","""")&""\""&INDEX(SPLIT($A$2,""_""),1)&""\""&INDEX(SPLIT($A$2,""_""),2)&""\""&SUBSTITUTE(SUBSTIT"&"UTE(SUBSTITUTE(SUBSTITUTE(SUBSTITUTE(INDEX(Hairstyles!$C:$C,MATCH($B11,Hairstyles!$F:$F,0)),"" "",""""),""'"",""""),""("",""""),"")"",""""),""-"",""_"")&""_""&$A$2)"),"Vanilla\Human\Male\Vanilla_BaldingShort4_Human_Male") -> Vanilla\Human\Male\Vanilla_BaldingShort4_Human_Male
B12: =IFERROR(__xludf.DUMMYFUNCTION("""COMPUTED_VALUE"""),"Uvi_Wig_Spell_VHRU_BaldingShort5") -> Uvi_Wig_Spell_VHRU_BaldingShort5 | C12: =IFERROR(__xludf.DUMMYFUNCTION("IF($B12="""","""",SUBSTITUTE(SUBSTITUTE(SUBSTITUTE(SUBSTITUTE(INDEX(Hairstyles!$A:$A,MATCH($B12,Hairstyles!$F:$F,0)),"" "",""""),""'"",""""),""("",""""),"")"","""")&""\""&INDEX(SPLIT($A$2,""_""),1)&""\""&INDEX(SPLIT($A$2,""_""),2)&""\""&SUBSTITUTE(SUBSTIT"&"UTE(SUBSTITUTE(SUBSTITUTE(SUBSTITUTE(INDEX(Hairstyles!$C:$C,MATCH($B12,Hairstyles!$F:$F,0)),"" "",""""),""'"",""""),""("",""""),"")"",""""),""-"",""_"")&""_""&$A$2)"),"Vanilla\Human\Male\Vanilla_BaldingShort5_Human_Male") -> Vanilla\Human\Male\Vanilla_BaldingShort5_Human_Male
B13: =IFERROR(__xludf.DUMMYFUNCTION("""COMPUTED_VALUE"""),"Uvi_Wig_Spell_VHRU_CornRowMohawk") -> Uvi_Wig_Spell_VHRU_CornRowMohawk | C13: =IFERROR(__xludf.DUMMYFUNCTION("IF($B13="""","""",SUBSTITUTE(SUBSTITUTE(SUBSTITUTE(SUBSTITUTE(INDEX(Hairstyles!$A:$A,MATCH($B13,Hairstyles!$F:$F,0)),"" "",""""),""'"",""""),""("",""""),"")"","""")&""\""&INDEX(SPLIT($A$2,""_""),1)&""\""&INDEX(SPLIT($A$2,""_""),2)&""\""&SUBSTITUTE(SUBSTIT"&"UTE(SUBSTITUTE(SUBSTITUTE(SUBSTITUTE(INDEX(Hairstyles!$C:$C,MATCH($B13,Hairstyles!$F:$F,0)),"" "",""""),""'"",""""),""("",""""),"")"",""""),""-"",""_"")&""_""&$A$2)"),"Vanilla\Human\Male\Vanilla_CornRowMohawk_Human_Male") -> Vanilla\Human\Male\Vanilla_CornRowMohawk_Human_Male
B14: =IFERROR(__xludf.DUMMYFUNCTION("""COMPUTED_VALUE"""),"Uvi_Wig_Spell_VHRU_CornRows") -> Uvi_Wig_Spell_VHRU_CornRows | C14: =IFERROR(__xludf.DUMMYFUNCTION("IF($B14="""","""",SUBSTITUTE(SUBSTITUTE(SUBSTITUTE(SUBSTITUTE(INDEX(Hairstyles!$A:$A,MATCH($B14,Hairstyles!$F:$F,0)),"" "",""""),""'"",""""),""("",""""),"")"","""")&""\""&INDEX(SPLIT($A$2,""_""),1)&""\""&INDEX(SPLIT($A$2,""_""),2)&""\""&SUBSTITUTE(SUBSTIT"&"UTE(SUBSTITUTE(SUBSTITUTE(SUBSTITUTE(INDEX(Hairstyles!$C:$C,MATCH($B14,Hairstyles!$F:$F,0)),"" "",""""),""'"",""""),""("",""""),"")"",""""),""-"",""_"")&""_""&$A$2)"),"Vanilla\Human\Male\Vanilla_CornRows_Human_Male") -> Vanilla\Human\Male\Vanilla_CornRows_Human_Male
B15: =IFERROR(__xludf.DUMMYFUNCTION("""COMPUTED_VALUE"""),"Uvi_Wig_Spell_VHRU_DreadlockMohawk") -> Uvi_Wig_Spell_VHRU_DreadlockMohawk | C15: =IFERROR(__xludf.DUMMYFUNCTION("IF($B15="""","""",SUBSTITUTE(SUBSTITUTE(SUBSTITUTE(SUBSTITUTE(INDEX(Hairstyles!$A:$A,MATCH($B15,Hairstyles!$F:$F,0)),"" "",""""),""'"",""""),""("",""""),"")"","""")&""\""&INDEX(SPLIT($A$2,""_""),1)&""\""&INDEX(SPLIT($A$2,""_""),2)&""\""&SUBSTITUTE(SUBSTIT"&"UTE(SUBSTITUTE(SUBSTITUTE(SUBSTITUTE(INDEX(Hairstyles!$C:$C,MATCH($B15,Hairstyles!$F:$F,0)),"" "",""""),""'"",""""),""("",""""),"")"",""""),""-"",""_"")&""_""&$A$2)"),"Vanilla\Human\Male\Vanilla_DreadlockMohawk_Human_Male") -> Vanilla\Human\Male\Vanilla_DreadlockMohawk_Human_Male
B16: =IFERROR(__xludf.DUMMYFUNCTION("""COMPUTED_VALUE"""),"Uvi_Wig_Spell_VHRU_DreadlockPonytail") -> Uvi_Wig_Spell_VHRU_DreadlockPonytail | C16: =IFERROR(__xludf.DUMMYFUNCTION("IF($B16="""","""",SUBSTITUTE(SUBSTITUTE(SUBSTITUTE(SUBSTITUTE(INDEX(Hairstyles!$A:$A,MATCH($B16,Hairstyles!$F:$F,0)),"" "",""""),""'"",""""),""("",""""),"")"","""")&""\""&INDEX(SPLIT($A$2,""_""),1)&""\""&INDEX(SPLIT($A$2,""_""),2)&""\""&SUBSTITUTE(SUBSTIT"&"UTE(SUBSTITUTE(SUBSTITUTE(SUBSTITUTE(INDEX(Hairstyles!$C:$C,MATCH($B16,Hairstyles!$F:$F,0)),"" "",""""),""'"",""""),""("",""""),"")"",""""),""-"",""_"")&""_""&$A$2)"),"Vanilla\Human\Male\Vanilla_DreadlockPonytail_Human_Male") -> Vanilla\Human\Male\Vanilla_DreadlockPonytail_Human_Male
B17: =IFERROR(__xludf.DUMMYFUNCTION("""COMPUTED_VALUE"""),"Uvi_Wig_Spell_VHRU_FrenchBraids") -> Uvi_Wig_Spell_VHRU_FrenchBraids | C17: =IFERROR(__xludf.DUMMYFUNCTION("IF($B17="""","""",SUBSTITUTE(SUBSTITUTE(SUBSTITUTE(SUBSTITUTE(INDEX(Hairstyles!$A:$A,MATCH($B17,Hairstyles!$F:$F,0)),"" "",""""),""'"",""""),""("",""""),"")"","""")&""\""&INDEX(SPLIT($A$2,""_""),1)&""\""&INDEX(SPLIT($A$2,""_""),2)&""\""&SUBSTITUTE(SUBSTIT"&"UTE(SUBSTITUTE(SUBSTITUTE(SUBSTITUTE(INDEX(Hairstyles!$C:$C,MATCH($B17,Hairstyles!$F:$F,0)),"" "",""""),""'"",""""),""("",""""),"")"",""""),""-"",""_"")&""_""&$A$2)"),"Vanilla\Human\Male\Vanilla_FrenchBraids_Human_Male") -> Vanilla\Human\Male\Vanilla_FrenchBraids_Human_Male
B18: =IFERROR(__xludf.DUMMYFUNCTION("""COMPUTED_VALUE"""),"Uvi_Wig_Spell_VHRU_FrenchBraidsHigh") -> Uvi_Wig_Spell_VHRU_FrenchBraidsHigh | C18: =IFERROR(__xludf.DUMMYFUNCTION("IF($B18="""","""",SUBSTITUTE(SUBSTITUTE(SUBSTITUTE(SUBSTITUTE(INDEX(Hairstyles!$A:$A,MATCH($B18,Hairstyles!$F:$F,0)),"" "",""""),""'"",""""),""("",""""),"")"","""")&""\""&INDEX(SPLIT($A$2,""_""),1)&""\""&INDEX(SPLIT($A$2,""_""),2)&""\""&SUBSTITUTE(SUBSTIT"&"UTE(SUBSTITUTE(SUBSTITUTE(SUBSTITUTE(INDEX(Hairstyles!$C:$C,MATCH($B18,Hairstyles!$F:$F,0)),"" "",""""),""'"",""""),""("",""""),"")"",""""),""-"",""_"")&""_""&$A$2)"),"Vanilla\Human\Male\Vanilla_FrenchBraidsHigh_Human_Male") -> Vanilla\Human\Male\Vanilla_FrenchBraidsHigh_Human_Male
B19: =IFERROR(__xludf.DUMMYFUNCTION("""COMPUTED_VALUE"""),"Uvi_Wig_Spell_VHRU_FrenchBraidsPonytail") -> Uvi_Wig_Spell_VHRU_FrenchBraidsPonytail | C19: =IFERROR(__xludf.DUMMYFUNCTION("IF($B19="""","""",SUBSTITUTE(SUBSTITUTE(SUBSTITUTE(SUBSTITUTE(INDEX(Hairstyles!$A:$A,MATCH($B19,Hairstyles!$F:$F,0)),"" "",""""),""'"",""""),""("",""""),"")"","""")&""\""&INDEX(SPLIT($A$2,""_""),1)&""\""&INDEX(SPLIT($A$2,""_""),2)&""\""&SUBSTITUTE(SUBSTIT"&"UTE(SUBSTITUTE(SUBSTITUTE(SUBSTITUTE(INDEX(Hairstyles!$C:$C,MATCH($B19,Hairstyles!$F:$F,0)),"" "",""""),""'"",""""),""("",""""),"")"",""""),""-"",""_"")&""_""&$A$2)"),"Vanilla\Human\Male\Vanilla_FrenchBraidsPonytail_Human_Male") -> Vanilla\Human\Male\Vanilla_FrenchBraidsPonytail_Human_Male
B20: =IFERROR(__xludf.DUMMYFUNCTION("""COMPUTED_VALUE"""),"Uvi_Wig_Spell_VHRU_FrenchBraidsSmall") -> Uvi_Wig_Spell_VHRU_FrenchBraidsSmall | C20: =IFERROR(__xludf.DUMMYFUNCTION("IF($B20="""","""",SUBSTITUTE(SUBSTITUTE(SUBSTITUTE(SUBSTITUTE(INDEX(Hairstyles!$A:$A,MATCH($B20,Hairstyles!$F:$F,0)),"" "",""""),""'"",""""),""("",""""),"")"","""")&""\""&INDEX(SPLIT($A$2,""_""),1)&""\""&INDEX(SPLIT($A$2,""_""),2)&""\""&SUBSTITUTE(SUBSTIT"&"UTE(SUBSTITUTE(SUBSTITUTE(SUBSTITUTE(INDEX(Hairstyles!$C:$C,MATCH($B20,Hairstyles!$F:$F,0)),"" "",""""),""'"",""""),""("",""""),"")"",""""),""-"",""_"")&""_""&$A$2)"),"Vanilla\Human\Male\Vanilla_FrenchBraidsSmall_Human_Male") -> Vanilla\Human\Male\Vanilla_FrenchBraidsSmall_Human_Male
B21: =IFERROR(__xludf.DUMMYFUNCTION("""COMPUTED_VALUE"""),"Uvi_Wig_Spell_VHRU_LooseBun") -> Uvi_Wig_Spell_VHRU_LooseBun | C21: =IFERROR(__xludf.DUMMYFUNCTION("IF($B21="""","""",SUBSTITUTE(SUBSTITUTE(SUBSTITUTE(SUBSTITUTE(INDEX(Hairstyles!$A:$A,MATCH($B21,Hairstyles!$F:$F,0)),"" "",""""),""'"",""""),""("",""""),"")"","""")&""\""&INDEX(SPLIT($A$2,""_""),1)&""\""&INDEX(SPLIT($A$2,""_""),2)&""\""&SUBSTITUTE(SUBSTIT"&"UTE(SUBSTITUTE(SUBSTITUTE(SUBSTITUTE(INDEX(Hairstyles!$C:$C,MATCH($B21,Hairstyles!$F:$F,0)),"" "",""""),""'"",""""),""("",""""),"")"",""""),""-"",""_"")&""_""&$A$2)"),"Vanilla\Human\Male\Vanilla_LooseBun_Human_Male") -> Vanilla\Human\Male\Vanilla_LooseBun_Human_Male
B22: =IFERROR(__xludf.DUMMYFUNCTION("""COMPUTED_VALUE"""),"Uvi_Wig_Spell_VHRU_MohawkLong") -> Uvi_Wig_Spell_VHRU_MohawkLong | C22: =IFERROR(__xludf.DUMMYFUNCTION("IF($B22="""","""",SUBSTITUTE(SUBSTITUTE(SUBSTITUTE(SUBSTITUTE(INDEX(Hairstyles!$A:$A,MATCH($B22,Hairstyles!$F:$F,0)),"" "",""""),""'"",""""),""("",""""),"")"","""")&""\""&INDEX(SPLIT($A$2,""_""),1)&""\""&INDEX(SPLIT($A$2,""_""),2)&""\""&SUBSTITUTE(SUBSTIT"&"UTE(SUBSTITUTE(SUBSTITUTE(SUBSTITUTE(INDEX(Hairstyles!$C:$C,MATCH($B22,Hairstyles!$F:$F,0)),"" "",""""),""'"",""""),""("",""""),"")"",""""),""-"",""_"")&""_""&$A$2)"),"Vanilla\Human\Male\Vanilla_MohawkLong_Human_Male") -> Vanilla\Human\Male\Vanilla_MohawkLong_Human_Male
B23: =IFERROR(__xludf.DUMMYFUNCTION("""COMPUTED_VALUE"""),"Uvi_Wig_Spell_VHRU_MohawkMessyLongBraid") -> Uvi_Wig_Spell_VHRU_MohawkMessyLongBraid | C23: =IFERROR(__xludf.DUMMYFUNCTION("IF($B23="""","""",SUBSTITUTE(SUBSTITUTE(SUBSTITUTE(SUBSTITUTE(INDEX(Hairstyles!$A:$A,MATCH($B23,Hairstyles!$F:$F,0)),"" "",""""),""'"",""""),""("",""""),"")"","""")&""\""&INDEX(SPLIT($A$2,""_""),1)&""\""&INDEX(SPLIT($A$2,""_""),2)&""\""&SUBSTITUTE(SUBSTIT"&"UTE(SUBSTITUTE(SUBSTITUTE(SUBSTITUTE(INDEX(Hairstyles!$C:$C,MATCH($B23,Hairstyles!$F:$F,0)),"" "",""""),""'"",""""),""("",""""),"")"",""""),""-"",""_"")&""_""&$A$2)"),"Vanilla\Human\Male\Vanilla_MohawkMessyLongBraid_Human_Male") -> Vanilla\Human\Male\Vanilla_MohawkMessyLongBraid_Human_Male
B24: =IFERROR(__xludf.DUMMYFUNCTION("""COMPUTED_VALUE"""),"Uvi_Wig_Spell_VHRU_MohawkMessyRingedBraids") -> Uvi_Wig_Spell_VHRU_MohawkMessyRingedBraids | C24: =IFERROR(__xludf.DUMMYFUNCTION("IF($B24="""","""",SUBSTITUTE(SUBSTITUTE(SUBSTITUTE(SUBSTITUTE(INDEX(Hairstyles!$A:$A,MATCH($B24,Hairstyles!$F:$F,0)),"" "",""""),""'"",""""),""("",""""),"")"","""")&""\""&INDEX(SPLIT($A$2,""_""),1)&""\""&INDEX(SPLIT($A$2,""_""),2)&""\""&SUBSTITUTE(SUBSTIT"&"UTE(SUBSTITUTE(SUBSTITUTE(SUBSTITUTE(INDEX(Hairstyles!$C:$C,MATCH($B24,Hairstyles!$F:$F,0)),"" "",""""),""'"",""""),""("",""""),"")"",""""),""-"",""_"")&""_""&$A$2)"),"Vanilla\Human\Male\Vanilla_MohawkMessyRingedBraids_Human_Male") -> Vanilla\Human\Male\Vanilla_MohawkMessyRingedBraids_Human_Male
B25: =IFERROR(__xludf.DUMMYFUNCTION("""COMPUTED_VALUE"""),"Uvi_Wig_Spell_VHRU_MohawkMessySideBraids") -> Uvi_Wig_Spell_VHRU_MohawkMessySideBraids | C25: =IFERROR(__xludf.DUMMYFUNCTION("IF($B25="""","""",SUBSTITUTE(SUBSTITUTE(SUBSTITUTE(SUBSTITUTE(INDEX(Hairstyles!$A:$A,MATCH($B25,Hairstyles!$F:$F,0)),"" "",""""),""'"",""""),""("",""""),"")"","""")&""\""&INDEX(SPLIT($A$2,""_""),1)&""\""&INDEX(SPLIT($A$2,""_""),2)&""\""&SUBSTITUTE(SUBSTIT"&"UTE(SUBSTITUTE(SUBSTITUTE(SUBSTITUTE(INDEX(Hairstyles!$C:$C,MATCH($B25,Hairstyles!$F:$F,0)),"" "",""""),""'"",""""),""("",""""),"")"",""""),""-"",""_"")&""_""&$A$2)"),"Vanilla\Human\Male\Vanilla_MohawkMessySideBraids_Human_Male") -> Vanilla\Human\Male\Vanilla_MohawkMessySideBraids_Human_Male
